Workbook

Sheet Knowledge Map
A1: Nature Repair Ontology — Biological Repair Logic → Engineering Reasoning | L1: 60-paper mapping snapshot
A2: Expanded from the 60-paper literature map and integrated with the attached reviews, primary studies, thesis, supporting information, and preprints. Core reasoning architecture: DETECT → STABILIZE / CONTAIN → MOBILIZE → RECONSTRUCT → REMODEL / VERIFY.
L3: Strategy | M3: Mapped evidence links
A4: Repair architecture: the sequence the engine should reason through | L4: =A15&" "&B15 -> NR01 Protect / prevent damage | M4: =J15 -> 2
A5: Phase | B5: Core question | C5: Nature logic | D5: Key ontology fields | E5: Representative strategies | L5: =A16&" "&B16 -> NR02 Contain / compartmentalize | M5: =J16 -> 0
A6: 0 PREVENT | B6: Can damage be avoided or reduced before repair is needed? | C6: Protect vulnerable tissue; renew exposed surfaces; deflect cracks. | D6: Damage type • exposure • protective layer • sacrificial zone | E6: NR01 Protect; NR07 Renew/Shed; NR10 Hierarchical crack control | L6: =A17&" "&B17 -> NR03 Rapid plug / seal | M6: =J17 -> 0
A7: 1 DETECT | B7: What changed, where, and how severe is it? | C7: Mechanical/chemical recognition initiates a local response. | D7: Sensor • threshold • location • feedback signal | E7: NR15 Sense→Signal→Repair | L7: =A18&" "&B18 -> NR04 Adhesive rejoin | M7: =J18 -> 10
A8: 2 STABILIZE / CONTAIN | B8: What must happen immediately to stop cascading failure? | C8: Clot, seal, isolate, sacrifice, or arrest propagation before full repair. | D8: Urgency • leak/ingress • propagation risk • containment boundary | E8: NR02 Contain; NR03 Plug/Seal; NR04 Adhesive rejoin; NR09 Sacrificial recovery | L8: =A19&" "&B19 -> NR05 Reservoir release | M8: =J19 -> 3
A9: 3 MOBILIZE | B9: Where do repair resources come from and how do they reach damage? | C9: Release stored material, transport through networks, recruit cells, or use ambient resources. | D9: Resource location • transport • energy • depletion • access | E9: NR05 Reservoir release; NR06 Vascular transport; NR14 Adaptive reconfiguration | L9: =A20&" "&B20 -> NR06 Vascular transport / replenishment | M9: =J20 -> 7
A10: 4 RECONSTRUCT | B10: How is continuity or missing material restored? | C10: Rebond, deposit mineral, regrow tissue, or recycle mobile matter. | D10: Reconstruction mode • scale • interface contact • chemistry | E10: NR08 Dynamic rebond; NR11 Biomineralize/Regrow; NR13 Dissolve→Redistribute→Redeploy | L10: =A21&" "&B21 -> NR07 Layer / renew / shed | M10: =J21 -> 0
A11: 5 REMODEL / VERIFY | B11: Has the relevant function returned, and can the system recover again? | C11: Remodel, restore multiple functions, monitor status, replenish resources. | D11: Function restored • recovery metric • cycles • depth • residual defect | E11: NR12 Living remodeling; NR15 Sense→Signal→Repair; NR16 Staged repair | L11: =A22&" "&B22 -> NR08 Dynamic rebond | M11: =J22 -> 33
L12: =A23&" "&B23 -> NR09 Sacrificial dissipation + recovery | M12: =J23 -> 10
A13: 16 reusable Nature Repair strategies | L13: =A24&" "&B24 -> NR10 Hierarchical crack control | M13: =J24 -> 20
A14: ID | B14: Strategy | C14: Primary phase | D14: Biological primitive | E14: Representative biological models | F14: Abstract engineering rule | G14: Typical trigger | H14: Repeatability | I14: Primary trade-off | J14: 60-paper links* | L14: =A25&" "&B25 -> NR11 Biomineralize / regrow missing material | M14: =J25 -> 6
A15: NR01 | B15: Protect / prevent damage | C15: 0 Prevent | D15: Protective surface | E15: Bark; arthropod exoskeleton; skin | F15: Place a durable or functional outer layer ahead of vulnerable structure so damage is absorbed, repelled, or slowed before it reaches critical material. | G15: Exposure / contact / environment | H15: Continuous if renewed | I15: Added layer can add mass, stiffness, or transport resistance | J15: =COUNTIF(Paper→Ontology!$E$5:$E$64,A15)+COUNTIF(Paper→Ontology!$F$5:$F$64,A15) -> 2 | L15: =A26&" "&B26 -> NR12 Living remodeling / regeneration | M15: =J26 -> 3
A16: NR02 | B16: Contain / compartmentalize | C16: 2 Stabilize | D16: Compartmentalization / boundary formation | E16: Trees (CODIT); immune barriers | F16: When full restoration is costly or risky, isolate the damaged zone with physical/chemical boundaries to prevent propagation. | G16: Damage / infection / ingress | H16: Potentially repeatable in new zones | I16: Sacrifices local function or material | J16: =COUNTIF(Paper→Ontology!$E$5:$E$64,A16)+COUNTIF(Paper→Ontology!$F$5:$F$64,A16) -> 0 | L16: =A27&" "&B27 -> NR13 Dissolve → redistribute → redeploy | M16: =J27 -> 0
A17: NR03 | B17: Rapid plug / seal | C17: 2 Stabilize | D17: Clotting / aggregation | E17: Blood clotting; hemolymph clotting; plant wound exudates | F17: Aggregate or precipitate material rapidly at the breach to stop leakage/ingress before slower reconstruction. | G17: Breach / fluid flow / local chemistry | H17: Usually limited unless resources replenish | I17: Fast sealing may not restore strength | J17: =COUNTIF(Paper→Ontology!$E$5:$E$64,A17)+COUNTIF(Paper→Ontology!$F$5:$F$64,A17) -> 0 | L17: =A28&" "&B28 -> NR14 Adaptive reconfiguration | M17: =J28 -> 9
A18: NR04 | B18: Adhesive rejoin | C18: 2 Stabilize | D18: Wet adhesion / interfacial bonding | E18: Mussel byssus; tissue adhesion | F18: Create high-affinity reversible or covalent interactions at damaged interfaces so separated surfaces reconnect under wet or dynamic conditions. | G18: Contact / water / pH / ions | H18: Multiple if bonds reversible | I18: Strong adhesion can reduce molecular mobility | J18: =COUNTIF(Paper→Ontology!$E$5:$E$64,A18)+COUNTIF(Paper→Ontology!$F$5:$F$64,A18) -> 10 | L18: =A29&" "&B29 -> NR15 Sense → signal → recruit / repair | M18: =J29 -> 11
A19: NR05 | B19: Reservoir release | C19: 3 Mobilize | D19: Vascular cells / capsules | E19: Weeping fig latex cells; secretory cells | F19: Store reactive resources separately and release them only when damage intersects the reservoir. | G19: Crack rupture / chemical trigger | H19: Often single-shot locally | I19: Finite payload; capsule must survive processing yet rupture on demand | J19: =COUNTIF(Paper→Ontology!$E$5:$E$64,A19)+COUNTIF(Paper→Ontology!$F$5:$F$64,A19) -> 3 | L19: =A30&" "&B30 -> NR16 Staged / temporal repair | M19: =J30 -> 6
A20: NR06 | B20: Vascular transport / replenishment | C20: 3 Mobilize | D20: Vascular network | E20: Blood vessels; plant vasculature | F20: Use connected channels to deliver, redistribute, and if possible replenish repair resources over distance and through repeated cycles. | G20: Pressure / capillarity / pumping / damage | H20: Multiple; potentially continuous with reservoir | I20: Network damage, blockage, complexity, volume penalty | J20: =COUNTIF(Paper→Ontology!$E$5:$E$64,A20)+COUNTIF(Paper→Ontology!$F$5:$F$64,A20) -> 7
A21: NR07 | B21: Layer / renew / shed | C21: 0 Prevent + 5 Remodel | D21: Layering + replenishable coating + abscission | E21: Snake skin; tree bark; lotus wax; plant abscission | F21: Continuously grow or replenish protective material from beneath; when damaged material is expendable, isolate then remove/shed it. | G21: Wear / growth / programmed biochemical trigger | H21: Continuous / periodic | I21: Consumes material/energy; discarded layer may be acceptable only in some systems | J21: =COUNTIF(Paper→Ontology!$E$5:$E$64,A21)+COUNTIF(Paper→Ontology!$F$5:$F$64,A21) -> 0
A22: NR08 | B22: Dynamic rebond | C22: 4 Reconstruct | D22: Reversible chemical/physical bonding | E22: Protein networks; ECM-like hydrogels; mussel-inspired networks | F22: Build reversible bonds into the load path so broken interfaces can reorganize and reconnect after damage. | G22: Contact; heat; water; pH; light; ions | H22: Multiple cycles | I22: Strength–mobility trade-off; surfaces often need re-contact | J22: =COUNTIF(Paper→Ontology!$E$5:$E$64,A22)+COUNTIF(Paper→Ontology!$F$5:$F$64,A22) -> 33
A23: NR09 | B23: Sacrificial dissipation + recovery | C23: 2 Stabilize + 4 Reconstruct | D23: Sacrificial bonds | E23: Mussel byssus; bone; nacre; tough tissue | F23: Let selected weaker bonds/domains fail first to dissipate energy while preserving the primary skeleton, then reform the sacrificial network. | G23: Mechanical load then unloading | H23: Multiple | I23: Dissipation may leave residual deformation; recovery kinetics matter | J23: =COUNTIF(Paper→Ontology!$E$5:$E$64,A23)+COUNTIF(Paper→Ontology!$F$5:$F$64,A23) -> 10
A24: NR10 | B24: Hierarchical crack control | C24: 0 Prevent + 2 Stabilize | D24: Hierarchy / crack deflection | E24: Tooth enamel; nacre; bone; fibrous tissue | F24: Arrange hard/soft phases and interfaces across scales to redistribute stress, deflect/blunt cracks, and preserve local mobility needed for repair. | G24: Mechanical damage / stress concentration | H24: Structural feature; not depleted | I24: Complex fabrication; too much reinforcement can suppress healing mobility | J24: =COUNTIF(Paper→Ontology!$E$5:$E$64,A24)+COUNTIF(Paper→Ontology!$F$5:$F$64,A24) -> 20
A25: NR11 | B25: Biomineralize / regrow missing material | C25: 4 Reconstruct | D25: Biomineralization / deposition | E25: Bone; shell; bacteria; fungi; algae | F25: Generate new solid phase in situ using local ions, metabolism, or crystallization so voids are filled rather than merely glued. | G25: Moisture; nutrients; ions; metabolism | H25: Multiple while agents/resources remain viable | I25: Resource access, environmental window, by-products, penetration depth | J25: =COUNTIF(Paper→Ontology!$E$5:$E$64,A25)+COUNTIF(Paper→Ontology!$F$5:$F$64,A25) -> 6
A26: NR12 | B26: Living remodeling / regeneration | C26: 5 Remodel | D26: Cellular growth + matrix turnover | E26: Skin; bone; tendon; regenerative tissue | F26: Continue rebuilding after closure: remove damaged material, replace matrix, reorganize structure, and restore function over longer time scales. | G26: Biological activity / load / signaling | H26: Continuous while living system remains viable | I26: Slow; resource- and control-intensive | J26: =COUNTIF(Paper→Ontology!$E$5:$E$64,A26)+COUNTIF(Paper→Ontology!$F$5:$F$64,A26) -> 3
A27: NR13 | B27: Dissolve → redistribute → redeploy | C27: 3 Mobilize + 4 Reconstruct | D27: Fibrinolysis / phase-transfer recycling | E27: Blood-vessel fibrinolysis analogue; Li–S self-healing electrolyte | F27: Convert obstructive or stranded material into a mobile phase, redistribute it, then reincorporate it into the functional cycle. | G27: Chemical potential / charge-discharge / solubility | H27: Multiple cycles | I27: Must suppress unwanted transport while enabling controlled remobilization | J27: =COUNTIF(Paper→Ontology!$E$5:$E$64,A27)+COUNTIF(Paper→Ontology!$F$5:$F$64,A27) -> 0
A28: NR14 | B28: Adaptive reconfiguration | C28: 3 Mobilize + 4 Reconstruct | D28: Reversible state change / rate-sensitive interactions | E28: Muscle; chameleon skin; bound-water networks; sea-cucumber-like adaptive tissue | F28: Change bond state, stiffness, transport, or architecture according to load rate or environment, then reverse when conditions normalize. | G28: Rate / strain / ions / water / temperature | H28: Multiple | I28: Response window and kinetics must match the disturbance | J28: =COUNTIF(Paper→Ontology!$E$5:$E$64,A28)+COUNTIF(Paper→Ontology!$F$5:$F$64,A28) -> 9
A29: NR15 | B29: Sense → signal → recruit / repair | C29: 1 Detect + 5 Verify | D29: Cellular signaling / mechanosensing | E29: Immune response; dermis; plant recognition; smart hydrogels | F29: Couple damage detection to a localized signal that recruits resources, changes chemistry, or reports repair status; measure functional recovery, not only closure. | G29: Stress; strain; chemistry; electrical / optical change | H29: Multiple if sensing path recovers | I29: Signal can recover differently from mechanics; false positives/threshold design | J29: =COUNTIF(Paper→Ontology!$E$5:$E$64,A29)+COUNTIF(Paper→Ontology!$F$5:$F$64,A29) -> 11
A30: NR16 | B30: Staged / temporal repair | C30: 2→5 sequence | D30: Sequential response / homeostasis | E30: Hemostasis→tissue repair; skin wound healing; plant multistage defense | F30: Assign different functions to different time scales: immediate stabilization first, then reconstruction, then remodeling/verification. | G30: Damage + time + evolving local conditions | H30: Multiple if underlying resources renew | I30: Coordination complexity; early response can obstruct later regeneration | J30: =COUNTIF(Paper→Ontology!$E$5:$E$64,A30)+COUNTIF(Paper→Ontology!$F$5:$F$64,A30) -> 6
A32: Cross-cutting constraints: what the reasoning engine must check before recommending a repair strategy
A33: Dimension | B33: Controlled values / examples | C33: Why it is first-class | D33: Failure if ignored
A34: Damage topology | B34: surface scratch • interface separation • microcrack • deep crack • distributed fatigue • missing volume | C34: Repair access and transport path differ by geometry. | D34: A surface can appear closed while the interior remains damaged.
A35: Function to restore | B35: barrier / watertightness • strength • stiffness • toughness • adhesion • electrical • actuation • biological | C35: 'Healed' must mean recovery of a named function. | D35: Self-sealing can be misreported as structural healing.
A36: Resource location | B36: intrinsic network • local capsule • distributed network • ambient • external • living/metabolic | C36: Determines autonomy and depletion. | D36: A one-shot capsule cannot support unlimited recurrence.
A37: Resource accessibility | B37: open surface • internal crack • vascularly accessible • light-exposed • moisture-exposed | C37: Biological agents and triggers need access. | D37: Algae may work at exposed surfaces but light is unavailable deep inside bulk concrete.
A38: Trigger / activation window | B38: damage • water • pH • heat • light/NIR • electrical • ions • strain rate • metabolism | C38: A mechanism is only useful if real operating conditions activate it. | D38: High-temperature healing chemistry may be impractical in service.
A39: Transport / penetration | B39: diffusion • capillarity • vascular flow • cell growth • ionic migration • none | C39: Controls how far repair reaches into damage. | D39: Crack-mouth closure may overestimate deep healing.
A40: Temporal profile | B40: seconds/minutes • hours • days • weeks • staged | C40: Urgent stabilization and full reconstruction often require different mechanisms. | D40: Slow healing may allow corrosion or crack growth before repair completes.
A41: Repeatability / depletion | B41: single-shot • finite multi-cycle • replenishable • continuous | C41: Sets lifecycle value. | D41: Finite reagents can be exhausted at recurrent damage sites.
...

Sheet Papers (60)
A1: Paper ID | B1: Cohort | C1: Year | D1: Title | E1: Journal | F1: Biological model | G1: Biological challenge | H1: Mechanism | I1: Abstracted design principle | J1: Primary strategy | K1: Secondary strategy | L1: Healing mode | M1: Trigger | N1: Repeatability | O1: Engineering implementation | P1: Application domain | Q1: Citation signal | R1: Source link (checked at compile) | S1: Notes | T1: Maturity level | U1: Maturity evidence | V1: Scale-up blocker | W1: ◄ Ontology function | X1: ◄ Ontology strategy | Y1: ◄ Operating principle
A2: B01 | B2: Base set | C2: 2026 | D2: Enamel-inspired composite with robust mechanical properties and self-healing capability | E2: Nature Communications | F2: Tooth enamel | G2: Remain stiff/strong while resisting crack propagation and restoring damage | H2: Aligned hydroxyapatite nanowires in a reversible borate-bond polymer network | I2: Combine hard aligned mineral architecture with a mobile, reversible interphase so strength and healing coexist | J2: S7 Hierarchical confinement / crack deflection | K2: S5 Dynamic rebonding | L2: Intrinsic / stimulus-assisted | M2: Heat + water | N2: Repeatable | O2: PVA/boric-acid/HAP nanowire composite | P2: Structural materials; automotive; construction | Q2: Recent 2026 | R2: https://www.nature.com/articles/s41467-026-72309-8 | S2: Validated 2026 paper; reported high healing efficiency and strong mechanical performance. | T2: Lab-scale (assumed) | U2: [VERIFY — inferred from paper type, not confirmed] | V2: [to complete] | W2: Strength | X2: Layering; crack deflection; load distribution | Y2: Multi-scale
A3: B02 | B3: Base set | C3: 2026 | D3: Bound water as a kinetic crosslinker for bio-inspired impact-stiffening polymers | E3: Nature Communications | F3: Water-mediated mechanics in biological materials | G3: Stay soft in normal use but stiffen and dissipate energy under rapid loading, then recover | H3: Bound water acts as a rate-sensitive kinetic crosslinker controlling intermolecular coupling | I3: Use a normally passive component as a load-rate-dependent temporary crosslinker | J3: S10 Adaptive remodeling / living repair | K3: S5 Dynamic rebonding | L3: Intrinsic / adaptive | M3: Impact / loading rate | N3: Repeatable | O3: Water-mediated dynamic polymer network | P3: Impact protection; adaptive structures | Q3: Recent 2026 | R3: https://www.nature.com/articles/s41467-026-75737-8 | S3: Mechanism is especially relevant to adaptive repair and impact response. | T3: Lab-scale (assumed) | U3: [VERIFY — inferred from paper type, not confirmed] | V3: [to complete] | W3: Adaptation | X3: Variation; behavioural flexibility | Y3: Self-repair
A4: B03 | B4: Base set | C4: 2026 | D4: Bioinspired Time-Gradient Self-Healing Polyurethane/Epoxy Covalent Dynamic Networks Enhanced by GO/ZIF-8@Curcumin for Marine Protection | E4: Small | F4: Skin wound healing | G4: Stabilize damage quickly, then rebuild more fully over time | H4: Fast extrinsic response combined with slower intrinsic dynamic-covalent reconstruction | I4: Sequence repair mechanisms rather than asking one mechanism to satisfy all time scales | J4: S9 Staged / temporal repair | K4: S5 Dynamic rebonding | L4: Hybrid intrinsic + extrinsic | M4: Ambient / time-dependent chemistry | N4: Repeatable | O4: PU/epoxy dynamic network + functional nanocontainers | P4: Marine anticorrosion coatings | Q4: Recent 2026 | R4: https://onlinelibrary.wiley.com/doi/10.1002/smll.74179 | S4: Strong exemplar of temporal sequencing. | T4: Lab-scale (assumed) | U4: [VERIFY — inferred from paper type, not confirmed] | V4: [to complete] | W4: Renewal | X4: Cyclicity; staged sequence | Y4: Spirality
A5: B04 | B5: Base set | C5: 2026 | D5: Bioinspired Self-Healing Polyurethane-Based Ionogel for Dual-Modal Strain Sensing and Solvent-Triggered Alerting | E5: Advanced Functional Materials | F5: Plant cell wall ion migration | G5: Maintain integrity while sensing deformation and environmental change | H5: Swelling-enhanced ion migration coupled to dynamic polyurethane bonding | I5: Couple repair with reversible ion transport so the same material can heal and sense | J5: S8 Sense → signal → repair | K5: S5 Dynamic rebonding | L5: Intrinsic / multifunctional | M5: Strain + solvent/environment | N5: Repeatable | O5: Polyurethane ionogel | P5: Wearables; strain sensing; chemical alerts | Q5: Recent 2026 | R5: https://advanced.onlinelibrary.wiley.com/doi/10.1002/adfm.76566 | S5: Explicitly plant-inspired. | T5: Lab-scale (assumed) | U5: [VERIFY — inferred from paper type, not confirmed] | V5: [to complete] | W5: Communication & feedback | X5: Closed feedback loop; damage signalling | Y5: Locality
A6: B05 | B6: Base set | C6: 2026 | D6: Skin-Inspired Design of Self-Healing Coatings Integrating Interface-Liquid Repellency and Corrosion Resistance | E6: Advanced Science | F6: Multilayer human skin | G6: Combine barrier protection, interface control, and healing without one function degrading another | H6: Layered/graded architecture with self-healing and liquid-repellent interfaces | I6: Spatially separate conflicting functions across layers and reconnect them after damage | J6: S1 Rapid seal / adhesion | K6: S9 Staged / temporal repair | L6: Intrinsic / layered | M6: Aqueous exposure + dynamic bonding | N6: Repeatable | O6: Multilayer protective coating | P6: Corrosion protection | Q6: Recent 2026 | R6: https://advanced.onlinelibrary.wiley.com/doi/10.1002/advs.202521067 | S6: Validated 2026 paper. | T6: Lab-scale (assumed) | U6: [VERIFY — inferred from paper type, not confirmed] | V6: [to complete] | W6: Protective envelope | X6: Selectively permeable boundary; surface sealing | Y6: Locality
A7: B06 | B7: Base set | C7: 2026 | D7: Dermis-Inspired Multimodal and Reversible Damaging-Healing Monitoring Coating via Dynamic Bonding Synchronous Activation Strategy | E7: Advanced Functional Materials | F7: Dermis / tissue damage signaling | G7: Detect accumulating damage and track healing progress while preserving protection | H7: Dynamic-bond reconstruction is coupled with a reversible optical signaling pathway | I7: Make damage and healing state observable in real time, not just mechanically repairable | J7: S8 Sense → signal → repair | K7: S5 Dynamic rebonding | L7: Intrinsic / self-reporting | M7: Mechanical damage + bond reconstruction | N7: Repeatable | O7: Smart protective coating | P7: Marine and structural coatings | Q7: Recent 2026 | R7: https://advanced.onlinelibrary.wiley.com/doi/10.1002/adfm.75334 | S7: Validated 2026 paper. | T7: Lab-scale (assumed) | U7: [VERIFY — inferred from paper type, not confirmed] | V7: [to complete] | W7: Communication & feedback | X7: Closed feedback loop; damage signalling | Y7: Locality
A8: B07 | B8: Base set | C8: 2026 | D8: Bioinspired super-tough polyurethane elastomers with block modules using sacrificial bonds | E8: RSC Advances | F8: Tough biological tissues / mussel byssus | G8: Absorb large deformation without catastrophic failure and recover reversible interactions | H8: Hierarchical sacrificial H-bonds and metal coordination in modular polyurethane | I8: Use multiple bond strengths so weaker bonds dissipate energy while stronger structure remains | J8: S6 Sacrificial-bond recovery | K8: S5 Dynamic rebonding | L8: Intrinsic | M8: Mechanical unloading / reversible bonding | N8: Repeatable | O8: Polyurethane elastomer | P8: E-skin; flexible devices; robotics | Q8: Recent 2026 | R8: https://pubs.rsc.org/en/content/articlelanding/2026/ra/d5ra08303f | S8: Explicitly bioinspired. | T8: Lab-scale (assumed) | U8: [VERIFY — inferred from paper type, not confirmed] | V8: [to complete] | W8: Strength | X8: Energy absorption; sacrificial bonds | Y8: Gradient
A9: B08 | B9: Base set | C9: 2026 | D9: Bioinspired Design of Strong, Tough, and Room-Temperature Healable Silicone Elastomers by Dynamic Nanoconfinement | E9: Macromolecules | F9: Hierarchical protein materials / spider-silk-like organization | G9: Combine high strength with chain mobility sufficient for room-temperature repair | H9: Dynamic nanoconfinement localizes strong interactions while leaving mobile healing domains | I9: Confine strong bonds spatially rather than making the whole network rigid | J9: S7 Hierarchical confinement / crack deflection | K9: S5 Dynamic rebonding | L9: Intrinsic | M9: Room temperature contact | N9: Repeatable | O9: Silicone elastomer | P9: Wearables; sensors; recyclable circuits | Q9: Recent 2026 | R9: https://pubs.acs.org/doi/10.1021/acs.macromol.6c00733 | S9: Validated 2026 paper. | T9: Lab-scale (assumed) | U9: [VERIFY — inferred from paper type, not confirmed] | V9: [to complete] | W9: Strength | X9: Layering; crack deflection; load distribution | Y9: Multi-scale
A10: B09 | B10: Base set | C10: 2026 | D10: Bio-Inspired Carbon Fiber/Epoxy Composites With Interfacial Self-Healing Ability Triggered by Electricity | E10: Polymer Composites | F10: Localized biological repair at damage-prone interfaces | G10: Restore damage preferentially where debonding occurs | H10: Electrically triggered interfacial healing chemistry concentrated at fiber/matrix interfaces | I10: Place repair capacity at known failure planes rather than distributing it uniformly | J10: S5 Dynamic rebonding | K10: S7 Hierarchical confinement / crack deflection | L10: Stimulus-assisted | M10: Electrical | N10: Repeated cycles | O10: Carbon-fiber/epoxy interface | P10: Aerospace; automotive composites | Q10: Recent 2026 | R10: https://4spepublications.onlinelibrary.wiley.com/doi/10.1002/pc.70926 | S10: Interface-localized repair exemplar. | T10: Lab-scale (assumed) | U10: [VERIFY — inferred from paper type, not confirmed] | V10: [to complete] | W10: Renewal | X10: Sacrificial bonds; re-bonding | Y10: Self-repair
A11: B10 | B11: Base set | C11: 2026 | D11: Bioinspired “self-healing vaccine” for cementitious materials: Physicochemical synergistic healing mechanisms among multiple cracks | E11: Cement and Concrete Research | F11: Vaccination / externally enabled biological response | G11: Enable existing infrastructure to respond repeatedly to future cracks | H11: External repair treatment supplies reactive resources that migrate/react in damaged cementitious zones | I11: Retrofit a repair capability into an existing system rather than requiring healing to be designed in from manufacture | J11: S4 Biomineralize / regrow | K11: S3 Vascular transport | L11: Extrinsic / externally supplied | M11: Moisture + treatment chemistry | N11: Potentially repeated | O11: Cementitious repair system | P11: Existing concrete infrastructure | Q11: Recent 2026 | R11: https://www.sciencedirect.com/science/article/abs/pii/S0008884626001304 | S11: Useful retrofit principle. | T11: Lab-scale (assumed) | U11: [VERIFY — inferred from paper type, not confirmed] | V11: [to complete] | W11: Renewal | X11: Regrowth; material cycling | Y11: Self-creation
A12: B11 | B12: Base set | C12: 2026 | D12: A strong, healable, recyclable bio-based adhesive via a bone-inspired triple network | E12: Journal of Materials Chemistry A | F12: Bone | G12: Combine stiffness, toughness, repair, and recyclability in one structural adhesive | H12: Triple-network hierarchy with reversible energy-dissipating interactions | I12: Assign different roles to nested networks: load bearing, dissipation, and repair | J12: S7 Hierarchical confinement / crack deflection | K12: S6 Sacrificial-bond recovery | L12: Intrinsic / thermally assisted | M12: Dynamic interactions | N12: Repeatable | O12: Bio-based structural adhesive | P12: Structural bonding | Q12: Recent 2026 | R12: https://pubs.rsc.org/en/content/articlelanding/2026/ta/d6ta01962e | S12: Bone-inspired hierarchy. | T12: Lab-scale (assumed) | U12: [VERIFY — inferred from paper type, not confirmed] | V12: [to complete] | W12: Strength | X12: Layering; crack deflection; load distribution | Y12: Multi-scale
... A61: A40 | B61: Added mechanism anchor | C61: 2017 | D61: Tough adhesives for diverse wet surfaces | E61: Science | F61: Biological wet adhesion / tough tissue interfaces | G61: Maintain strong adhesion to wet, moving, deformable tissues | H61: A dissipative matrix is combined with strong interfacial bonding to create high interfacial toughness | I61: Pair adhesion chemistry with a bulk energy-dissipation layer; interface strength alone is not enough | J61: S1 Rapid seal / adhesion | K61: S6 Sacrificial-bond recovery | L61: Interfacial / tough adhesive | M61: Contact + wet bonding | N61: Reusable concept; formulation dependent | O61: Tough hydrogel adhesive | P61: Tissue sealing; wet structural adhesion | Q61: >1,700 citations surfaced | R61: https://www.science.org/doi/10.1126/science.aah6362 | S61: Mechanism anchor for durable sealing and repair interfaces. | T61: N/A — biological mechanism | U61: Nature, not an engineered system | V61: — | W61: Protective envelope | X61: Selectively permeable boundary; surface sealing | Y61: Locality

Sheet Engine Schema
A1: Nature Repair Ontology — AI / knowledge-graph schema
A2: Recommended data model for converting biological evidence and engineering papers into reasoning-ready records. The engine should retrieve mechanisms by challenge/constraint, not by organism name alone.
A4: Field | B4: Entity / layer | C4: Question the engine answers | D4: Controlled vocabulary / data type | E4: Example | F4: Reasoning role | G4: Required? | H4: Validation rule / caveat
A5: Record_ID | B5: All | C5: What unique assertion/model/paper/strategy is this? | D5: Unique string | E5: BIO-M19 / STR-NR11 / PAP-B01 | F5: Graph identity | G5: Yes | H5: Never reuse IDs across entity types.
A6: Entity_Type | B6: All | C6: What kind of thing is this record? | D6: BiologicalModel / Primitive / Strategy / Paper / Relation / Metric / ChallengeRule | E6: Strategy | F6: Routing | G6: Yes | H6: Controls which fields are applicable.
A7: Biological_Model_ID | B7: Biological evidence | C7: Which organism/tissue/system demonstrates the mechanism? | D7: M01–M30 + expandable | E7: M19 CODIT | F7: Evidence anchor | G7: When biological | H7: One model can map to multiple primitives/strategies.
A8: Biological_Domain | B8: Biological evidence | C8: What type of living system is it? | D8: Animal / plant / microorganism / tissue / cellular / ecological | E8: Woody plant | F8: Transfer context | G8: Recommended | H8: Do not infer taxonomy beyond source support.
A9: Damage_or_Challenge | B9: Problem | C9: What failure must be prevented or repaired? | D9: Functional sentence + damage tags | E9: Stop crack-mediated fluid ingress | F9: Problem abstraction | G9: Yes | H9: State damage, not solution.
A10: Damage_Topology | B10: Problem | C10: What is the geometry/location of damage? | D10: Surface / interface / microcrack / deep crack / distributed / missing volume / deposit | E10: Deep crack | F10: Feasibility filter | G10: Yes | H10: Needed for penetration/access reasoning.
A11: Damage_Severity | B11: Problem | C11: How large/severe is the defect? | D11: Numeric + units + class | E11: 0.4 mm crack | F11: Scale matching | G11: If known | H11: Store original measured value.
A12: Repair_Phase | B12: Ontology | C12: At which step does the mechanism act? | D12: 0 Prevent / 1 Detect / 2 Stabilize / 3 Mobilize / 4 Reconstruct / 5 Remodel-Verify | E12: 3 Mobilize | F12: Sequence planning | G12: Yes | H12: Multi-phase values allowed.
A13: Primitive_IDs | B13: Biological mechanism | C13: What minimal natural actions are present? | D13: P01–P16 array | E13: P06,P11 | F13: Mechanism decomposition | G13: Yes | H13: Prefer evidence-backed primitive assignment.
A14: Strategy_IDs | B14: Engineering abstraction | C14: Which reusable repair strategy/strategies apply? | D14: NR01–NR16 array | E14: NR06,NR11 | F14: Strategy retrieval | G14: Yes | H14: Primary + complementary strategy order matters.
A15: Mechanism | B15: Causal layer | C15: How does the natural/engineered system actually work? | D15: Evidence-backed prose / structured steps | E15: Damage releases latex; capillarity carries it into wound | F15: Causal reasoning | G15: Yes | H15: Avoid metaphor-only descriptions.
... A51: Transfer_Rule | B51: Reasoning output | C51: Under what conditions may this mechanism transfer to another domain? | D51: IF–THEN rule | E51: IF damage recurs at unknown internal locations AND fluid channels are feasible THEN prioritize NR06 | F51: Concept generation | G51: Yes for strategy records | H51: Must include constraints, not only benefits.
A54: Core relation vocabulary for a future knowledge graph
A55: Relation | B55: Meaning | C55: Example
A56: USES_PRIMITIVE | B56: Biological model or strategy employs primitive | C56: M19 USES_PRIMITIVE P09
A57: INSPIRES | B57: Biological model provides causal inspiration for strategy | C57: M03 INSPIRES NR13
A58: TRIGGERED_BY | B58: Response activates under condition | C58: NR11 TRIGGERED_BY moisture/nutrients
A59: REQUIRES | B59: Mechanism is infeasible without condition/resource | C59: NR08 REQUIRES molecular mobility
A60: LIMITED_BY | B60: Known failure boundary | C60: NR05 LIMITED_BY finite payload
A61: PRECEDES | B61: Temporal order | C61: NR03 PRECEDES NR12
A62: COMPLEMENTS | B62: Strategies improve each other | C62: NR10 COMPLEMENTS NR08
A63: CONFLICTS_WITH | B63: One response can impede another | C63: NR03 CAN CONFLICT WITH deep transport
A64: RESTORES_FUNCTION | B64: Names recovered capability | C64: NR03 RESTORES_FUNCTION barrier
A65: MEASURE_WITH | B65: Links strategy to metric ontology | C65: NR11 MEASURE_WITH E01,E02,E03,E04
A66: NOT_EQUIVALENT_TO | B66: Prevents category errors | C66: Self-sealing NOT_EQUIVALENT_TO strength recovery

Sheet Legacy Map (10)
A1: Nature Self-Healing Knowledge Map
A2: 60 validated academic papers mapped by reusable biological repair strategy • 20-paper base set + 40 additional high-impact / foundational papers
A4: Strategy | B4: Biological analogs | C4: What nature solves | D4: Abstracted design principle | E4: Typical engineering translation | F4: Typical triggers | G4: Paper count | I4: Strategy profile | J4: Papers
A5: S1 Rapid seal / adhesion | B5: Mussels, skin, clotting/tissue closure | C5: Create fast wet adhesion or sealing at the damaged interface to stop further ingress, leakage, or separation. | D5: Dynamic catechol/metal, covalent tissue bonding, reversible adhesive interfaces | E5: Adhesive hydrogel/coating/interface that closes or seals a damaged boundary before secondary damage propagates. | F5: Water, pH, contact, local chemistry | G5: 7 | I5: Rapid seal / adhesion | J5: 7
A6: S2 Reservoir release | B6: Cells/organisms storing and releasing repair resources | C6: Store healing agents locally; damage ruptures a reservoir and releases material exactly where needed. | D6: Microcapsules, hollow fibers, sacrificial reservoirs | E6: Embed microcapsules/reservoirs that rupture on crack formation and release healing chemistry locally. | F6: Crack rupture / mechanical damage | G6: 1 | I6: Reservoir release | J6: 1
A7: S3 Vascular transport | B7: Blood vessels, plant vasculature | C7: Use connected channels to transport and replenish healing agents so repair can occur repeatedly and over larger volumes. | D7: Microvascular networks, multi-channel delivery, replenishable vascules | E7: Build refillable microchannel networks that deliver repair agents repeatedly to damaged zones. | F7: Damage-induced flow, pressure, pumping | G7: 6 | I7: Vascular transport | J7: 6
A8: S4 Biomineralize / regrow | B8: Bone, shell formation, microbial biomineralization | C8: Generate new solid material in situ to fill defects and restore barrier or load-bearing function. | D8: Bacteria-induced CaCO3, mineral precipitation, regenerative matrices | E8: Generate new mineral/solid phase in situ through microbes, ions, or precipitation rather than merely gluing cracks. | F8: Moisture, nutrients, microbial metabolism | G8: 6 | I8: Biomineralize / regrow | J8: 6
A9: S5 Dynamic rebonding | B9: Protein networks, mussel catechol chemistry, squid ring teeth | C9: Use reversible bonds that break under damage and re-form afterward, enabling repeatable repair. | D9: H-bonds, metal-ligand bonds, boronate esters, imines, dynamic covalent networks | E9: Use reversible covalent, hydrogen-bond, ionic, metal–ligand, or supramolecular bonds that re-form after damage. | F9: Ambient contact, heat, pH, water, ions | G9: 10 | I9: Dynamic rebonding | J9: 10
A10: S6 Sacrificial-bond recovery | B10: Mussel byssus, bone, nacre, tough biological tissues | C10: Allow selected weaker bonds/domains to fail first, dissipate energy, then reconnect while the main structure survives. | D10: Hierarchical weak/strong bonds, metal-catechol, multiple H-bond domains | E10: Place weaker reversible bonds ahead of the load-bearing network so they dissipate energy, then recover. | F10: Mechanical loading followed by rebonding | G10: 4 | I10: Sacrificial-bond recovery | J10: 4
A11: S7 Hierarchical confinement / crack deflection | B11: Nacre, enamel, bone, vascular smooth muscle, squid ring teeth | C11: Control damage path across scales; use hard-soft hierarchy, nanoconfinement, and interfaces to blunt/deflect cracks while retaining mobility for healing. | D11: Brick-and-mortar architectures, aligned platelets/nanowires, confined dynamic phases, core-shell inclusions | E11: Use hard–soft hierarchy, aligned reinforcement, interfaces or nanoconfinement to arrest cracks while preserving local mobility. | F11: Heat, local mobility, deformation | G11: 10 | I11: Hierarchy / crack deflection | J11: 10
A12: S8 Sense → signal → repair | B12: Skin, mechanoreceptors, plant ion transport | C12: Couple damage detection with a visible/electrical/mechanical signal and activate or monitor repair. | D12: Mechanochromism, ion transport, conductive pathways, damage-responsive chemistry | E12: Couple damage detection to optical/electrical/mechanical signaling and, ideally, activation of the repair pathway. | F12: Stress, strain, solvent, pressure, electrical/NIR | G12: 8 | I12: Sense → signal → repair | J12: 8
A13: S9 Staged / temporal repair | B13: Skin wound healing, embryonic wound closure | C13: Sequence different repair functions over time: fast stabilization first, slower structural restoration later. | D13: Fast extrinsic + slow intrinsic repair; time-gradient chemistry | E13: Assign different repair functions to different time scales: rapid stabilization first, slower reconstruction afterward. | F13: Time, local chemistry, temperature | G13: 2 | I13: Staged / temporal repair | J13: 2
A14: S10 Adaptive remodeling / living repair | B14: Sea cucumber dermis, living tissues, regenerative systems | C14: Adapt stiffness/function to the environment, then remodel or regenerate rather than merely close a crack. | D14: Stimuli-responsive networks, living materials, regenerative hydrogels | E14: Allow stiffness, architecture or biological activity to adapt over time and rebuild function rather than simply close a defect. | F14: Water, ionic environment, biological activity, external stimuli | G14: 6 | I14: Adaptive / living repair | J14: 6
A17: Cross-cutting dimensions for a Nature Intelligence self-healing reasoning engine
A18: Dimension | B18: Possible values | C18: Why it matters | D18: Example biological logic
A19: Trigger | B19: Damage • water • pH • heat • light/NIR • electrical • enzymatic • microbial • spontaneous | C19: Defines what initiates repair and whether external energy is required. | D19: Wounds activate coagulation; plants respond to moisture/ionic changes.
A20: Resource location | B20: Local • embedded capsule • distributed network • external • living | C20: Determines how repair resources are stored and replenished. | D20: Cells store factors locally; vascular systems transport resources.
A21: Repair scale | B21: Molecular • interface • microcrack • macrocrack • tissue/structure | C21: Prevents choosing a mechanism that operates at the wrong damage scale. | D21: Proteins rebind molecularly while bone remodels across larger volumes.
A22: Repeatability | B22: Single-shot • multiple-cycle • continuous | C22: Separates one-time emergency repair from durable regenerative capability. | D22: Capsules are often one-shot; vascular/living systems can replenish.
A23: Autonomy | B23: Autonomous • stimulus-assisted • externally replenished | C23: Controls system complexity, energy demand and maintenance burden. | D23: Skin heals autonomously; some biological processes depend on external nutrients.
A24: Temporal profile | B24: Immediate • staged • delayed • slow remodeling | C24: Allows repair architecture to optimize speed versus completeness. | D24: Hemostasis is rapid; tissue remodeling is slower.
A25: Feedback | B25: None • visual • electrical • mechanical • chemical | C25: Enables the material/system to report damage and repair status. | D25: Inflammatory signaling and mechanosensing provide feedback.
A26: Function restored | B26: Mechanical • barrier • electrical • adhesion • actuation • biological | C26: Defines what 'healed' actually means in system performance terms. | D26: Different tissues prioritize barrier, load bearing, signaling or motion.

Sheet Paper→Ontology
A1: Mapping of the existing 60-paper evidence base into the Nature Repair Ontology
A2: This is a taxonomy mapping layer: it preserves the original paper metadata while assigning ontology strategy IDs. It does not replace paper-level mechanism extraction.
A4: Paper ID | B4: Year | C4: Title | D4: Biological model | E4: Ontology primary | F4: Ontology secondary | G4: Repair phase | H4: Trigger | I4: Repeatability | J4: Validated source
A5: B01 | B5: 2026 | C5: Enamel-inspired composite with robust mechanical properties and self-healing capability | D5: Tooth enamel | E5: NR10 | F5: NR08 | G5: 0 Prevent / 2 Stabilize | H5: Heat + water | I5: Repeatable | J5: https://www.nature.com/articles/s41467-026-72309-8
A6: B02 | B6: 2026 | C6: Bound water as a kinetic crosslinker for bio-inspired impact-stiffening polymers | D6: Water-mediated mechanics in biological materials | E6: NR14 | F6: NR08 | G6: 3 Mobilize / 4 Reconstruct | H6: Impact / loading rate | I6: Repeatable | J6: https://www.nature.com/articles/s41467-026-75737-8
A7: B03 | B7: 2026 | C7: Bioinspired Time-Gradient Self-Healing Polyurethane/Epoxy Covalent Dynamic Networks Enhanced by GO/ZIF-8@Curcumin for Marine Protection | D7: Skin wound healing | E7: NR16 | F7: NR08 | G7: 2–5 staged | H7: Ambient / time-dependent chemistry | I7: Repeatable | J7: https://onlinelibrary.wiley.com/doi/10.1002/smll.74179
A8: B04 | B8: 2026 | C8: Bioinspired Self-Healing Polyurethane-Based Ionogel for Dual-Modal Strain Sensing and Solvent-Triggered Alerting | D8: Plant cell wall ion migration | E8: NR15 | F8: NR08 | G8: 1 Detect / 5 Verify | H8: Strain + solvent/environment | I8: Repeatable | J8: https://advanced.onlinelibrary.wiley.com/doi/10.1002/adfm.76566
A9: B05 | B9: 2026 | C9: Skin-Inspired Design of Self-Healing Coatings Integrating Interface-Liquid Repellency and Corrosion Resistance | D9: Multilayer human skin | E9: NR01 | F9: NR16 | G9: 0 Prevent | H9: Aqueous exposure + dynamic bonding | I9: Repeatable | J9: https://advanced.onlinelibrary.wiley.com/doi/10.1002/advs.202521067
A10: B06 | B10: 2026 | C10: Dermis-Inspired Multimodal and Reversible Damaging-Healing Monitoring Coating via Dynamic Bonding Synchronous Activation Strategy | D10: Dermis / tissue damage signaling | E10: NR15 | F10: NR08 | G10: 1 Detect / 5 Verify | H10: Mechanical damage + bond reconstruction | I10: Repeatable | J10: https://advanced.onlinelibrary.wiley.com/doi/10.1002/adfm.75334
A11: B07 | B11: 2026 | C11: Bioinspired super-tough polyurethane elastomers with block modules using sacrificial bonds | D11: Tough biological tissues / mussel byssus | E11: NR09 | F11: NR08 | G11: 2 Stabilize / 4 Reconstruct | H11: Mechanical unloading / reversible bonding | I11: Repeatable | J11: https://pubs.rsc.org/en/content/articlelanding/2026/ra/d5ra08303f
A12: B08 | B12: 2026 | C12: Bioinspired Design of Strong, Tough, and Room-Temperature Healable Silicone Elastomers by Dynamic Nanoconfinement | D12: Hierarchical protein materials / spider-silk-like organization | E12: NR10 | F12: NR08 | G12: 0 Prevent / 2 Stabilize | H12: Room temperature contact | I12: Repeatable | J12: https://pubs.acs.org/doi/10.1021/acs.macromol.6c00733
A13: B09 | B13: 2026 | C13: Bio-Inspired Carbon Fiber/Epoxy Composites With Interfacial Self-Healing Ability Triggered by Electricity | D13: Localized biological repair at damage-prone interfaces | E13: NR08 | F13: NR10 | G13: 4 Reconstruct | H13: Electrical | I13: Repeated cycles | J13: https://4spepublications.onlinelibrary.wiley.com/doi/10.1002/pc.70926
A14: B10 | B14: 2026 | C14: Bioinspired “self-healing vaccine” for cementitious materials: Physicochemical synergistic healing mechanisms among multiple cracks | D14: Vaccination / externally enabled biological response | E14: NR11 | F14: NR06 | G14: 4 Reconstruct | H14: Moisture + treatment chemistry | I14: Potentially repeated | J14: https://www.sciencedirect.com/science/article/abs/pii/S0008884626001304
A15: B11 | B15: 2026 | C15: A strong, healable, recyclable bio-based adhesive via a bone-inspired triple network | D15: Bone | E15: NR10 | F15: NR09 | G15: 0 Prevent / 2 Stabilize | H15: Dynamic interactions | I15: Repeatable | J15: https://pubs.rsc.org/en/content/articlelanding/2026/ta/d6ta01962e
... A64: A40 | B64: 2017 | C64: Tough adhesives for diverse wet surfaces | D64: Biological wet adhesion / tough tissue interfaces | E64: NR04 | F64: NR09 | G64: 2 Stabilize / 4 Reconstruct | H64: Contact + wet bonding | I64: Reusable concept; formulation dependent | J64: https://www.science.org/doi/10.1126/science.aah6362

Sheet Repair Strategies
A1: Nature Repair Ontology — Strategy Definitions and Transfer Rules
A2: Each strategy is a reusable engineering-neutral repair pattern. Biological models are evidence anchors; constraints and failure modes are first-class so the engine can reject unsuitable analogies.
A4: Strategy ID | B4: Strategy | C4: Repair phase(s) | D4: Canonical / extended primitive | E4: Representative biological model | F4: Biological challenge | G4: Natural sequence | H4: Trigger / sensor | I4: Immediate response | J4: Resource / repair material | K4: Resource location | L4: Transport / mobilization | M4: Reconstruction mode | N4: Spatial scale | O4: Temporal profile | P4: Repeatability | Q4: Function(s) restored | R4: Engineering-neutral design rule | S4: Suitable engineering conditions | T4: Main trade-off | U4: Common failure mode | V4: Best complementary strategies | W4: Evidence anchors | X4: Confidence
A5: NR01 | B5: Protect / prevent damage | C5: 0 Prevent | D5: Canonical: protective surface | E5: Tree bark; arthropod exoskeleton; skin; functional plant surfaces | F5: Keep routine environmental or mechanical damage away from vulnerable tissue. | G5: Build tough/functional outer layer → absorb/repel exposure → renew from beneath if needed. | H5: Exposure / contact; often passive | I5: Damage is prevented or shifted to expendable layer | J5: Protective material / surface chemistry | K5: Surface / outer layer | L5: None or replenishment from below | M5: Barrier formation; repellency; sacrificial absorption | N5: Surface → component | O5: Continuous | P5: Continuous if renewed | Q5: Barrier integrity; environmental protection | R5: Put a robust, task-specific layer ahead of vulnerable functions; design that layer to be renewable or sacrificial when possible. | S5: High exposure frequency; surface-dominated failure; contamination/corrosion/fouling risk | T5: Added thickness/mass can impede transport or flexibility | U5: Barrier cracks without renewal; hidden sub-surface damage | V5: NR07, NR10, NR15 | W5: Cremaldi & Bhushan 2018; Youngblood & Sottos 2008 | X5: High
A6: NR02 | B6: Contain / compartmentalize | C6: 2 Stabilize | D6: Extended: boundary formation / damage containment | E6: Trees — compartmentalization of decay (CODIT); immune barriers | F6: Prevent a local defect, infection, or degradation zone from spreading through the whole system. | G6: Detect local damage → form physical + chemical walls → sacrifice/isolate damaged region → continue operation elsewhere. | H6: Local damage / disease chemistry | I6: Propagation pathway is cut | J6: Boundary-forming material / chemistry | K6: At perimeter of damaged zone | L6: Local secretion / growth | M6: Isolation rather than restoration | N6: Local zone → component | O6: Fast boundary formation then persistent | P6: Repeatable in new zones | Q6: System-level continuity / integrity | R6: If full repair is expensive or risky, isolate the failing zone and preserve the rest of the system. | S6: Distributed systems; non-critical local loss acceptable; propagation risk high | T6: Local capacity is sacrificed | U6: Boundary is incomplete; damage bypasses compartment | V6: NR01, NR03, NR16 | W6: Cremaldi & Bhushan 2018 — CODIT | X6: High
A7: NR03 | B7: Rapid plug / seal | C7: 2 Stabilize | D7: Canonical: clotting / aggregation | E7: Blood clotting; invertebrate hemolymph clotting; plant wound secretions | F7: Stop fast loss of fluid or ingress of harmful agents immediately after breach. | G7: Breach → local aggregation/precipitation → plug forms → flow/ingress drops → slower repair follows. | H7: Breach / flow / exposed chemistry | I7: Wound is sealed rapidly | J7: Platelets/proteins/exudate or precipitating material | K7: Circulating or locally stored | L7: Flow + aggregation / capillarity | M7: Plug / precipitate / temporary barrier | N7: Interface / crack | O7: Seconds–minutes biologically; application-dependent | P7: Finite unless replenished | Q7: Barrier / watertightness | R7: Prioritize a fast sealing mechanism that stabilizes the defect even if it does not yet restore load-bearing performance. | S7: Leakage, ingress, corrosion exposure, puncture-like damage | T7: Fast closure can obstruct later reconstruction or provide little mechanical strength | U7: Surface closure mistaken for full-depth healing | V7: NR06, NR11, NR16 | W7: Cremaldi & Bhushan 2018; concrete sealing literature | X7: High
A8: NR04 | B8: Adhesive rejoin | C8: 2 Stabilize + 4 Reconstruct | D8: Extended: wet adhesion / interfacial rebonding | E8: Mussel byssus / adhesive plaque; tissue interfaces | F8: Reconnect separated interfaces under wet, dynamic, or contaminated conditions. | G8: Bring faces into contact → form high-affinity interfacial bonds → dissipate load → reversible bonds reform after disturbance. | H8: Contact; pH; water; ions | I8: Interface reconnects | J8: Catechol-like groups / dynamic bonds | K8: At damaged interface | L8: Diffusion / molecular contact | M8: Adhesive bonding | N8: Molecular → interface | O8: Minutes–hours | P8: Multiple if dynamic | Q8: Adhesion; barrier; sometimes mechanics | R8: Design the damaged interface itself as an active repair zone using reversible, water-compatible, high-affinity interactions. | S8: Delamination, wet adhesion, coatings, tissue interfaces | T8: High bond density can reduce chain mobility | U8: Faces do not re-contact; fouling blocks bonding | V8: NR08, NR09, NR15 | W8: Mussel-inspired papers in 60-paper set | X8: High
A9: NR05 | B9: Reservoir release | C9: 3 Mobilize | D9: Canonical: vascular cells / capsules | E9: Weeping fig latex cells; secretory cells; biological vesicle-like storage | F9: Keep reactive repair resources stable until damage occurs, then release exactly at the wound. | G9: Store agent → damage ruptures container / changes chemistry → agent is released → flows into defect → reacts/solidifies. | H9: Crack rupture; pH; chloride; heat; moisture; electromagnetic trigger | I9: Localized agent release | J9: Healing monomer/resin/mineral precursor/cells | K9: Distributed capsules / granules | L9: Capillarity / local flow | M9: Polymerization / precipitation / swelling | N9: Microcrack → local macrocrack | O9: Fast to hours/days | P9: Usually single-shot at a location | Q9: Barrier + mechanics depending agent | R9: Separate reactive chemistry from the host until a damage-specific trigger releases it. | S9: Sparse unpredictable cracks; manufacturing can tolerate inclusions | T9: Finite payload; capsules change host mechanics | U9: Premature rupture; no capsule intersects crack; payload exhausted | V9: NR03, NR11, NR16 | W9: White et al. 2001 lineage; van der Bergh thesis capsule classification | X9: High
A10: NR06 | B10: Vascular transport / replenishment | C10: 3 Mobilize | D10: Canonical: vascular networks | E10: Blood vessels; plant vasculature; refillable biological transport | F10: Deliver cells, nutrients, enzymes, or repair chemistry over distance and repeatedly. | G10: Damage creates demand → connected network supplies agent → flow reaches defect → repair occurs → reservoir can refill network. | H10: Damage-induced pressure/capillarity or active pumping | I10: Repair resources reach wound | J10: Fluid healing agent / nutrients / cells | K10: Distributed channel network + reservoir | L10: Flow through 1D/2D/3D network | M10: Chemical repair / deposition / replenishment | N10: Microcrack → component | O10: Minutes–days | P10: Multi-cycle; potentially continuous if externally replenished | Q10: Barrier; mechanics; function-specific | R10: Use a connected distribution network when damage is recurrent, internal, or requires more material than a local reservoir can hold. | S10: Repeated same-zone damage; large components; inaccessible internal cracks | T10: Network volume and complexity; network itself can fail | U10: Channel blockage/cut; insufficient pressure; no path to damage | V10: NR05, NR11, NR15 | W10: Cremaldi & Bhushan 2018; microvascular self-healing literature | X10: High
A11: NR07 | B11: Layer / renew / shed | C11: 0 Prevent + 5 Remodel | D11: Canonical: layering + replenishable coatings; extended: abscission | E11: Snake molting; tree bark; lotus wax; plant abscission | F11: Maintain a healthy exposed surface despite wear, fouling, or local damage. | G11: Grow/replenish new layer from within → protect next layer → optionally weaken boundary → shed damaged/old material. | H11: Wear; growth; programmed biochemical signal | I11: Fresh surface is exposed | J11: New layer / wax / secreted material | K11: Produced beneath or at surface | L11: Growth / secretion | M11: Replacement rather than patching | N11: Surface | O11: Periodic / continuous | P11: Continuous with resource supply | Q11: Surface protection / cleanliness | R11: When the outer layer is expendable, replace it instead of repeatedly repairing the same degraded material. | S11: High-cycle surface wear; coatings; self-cleaning; replaceable skins | T11: Consumes material and creates waste | U11: Replacement rate too slow; shedding damages substrate | V11: NR01, NR02, NR16 | W11: Cremaldi & Bhushan 2018 — layering, lotus, abscission | X11: High
A12: NR08 | B12: Dynamic rebond | C12: 4 Reconstruct | D12: Extended: reversible molecular network | E12: Protein networks; extracellular-matrix-like hydrogels; mussel-inspired coordination | F12: Restore continuity after bonds break while preserving repeated use. | G12: Damage breaks reversible bonds → chain/segment mobility enables recontact → bonds exchange/reform → network continuity returns. | H12: Contact; heat; water; pH; light; ions | I12: Broken network reconnects | J12: Intrinsic dynamic bonds | K12: Distributed throughout matrix/interface | L12: Molecular diffusion / exchange | M12: Dynamic covalent or supramolecular rebonding | N12: Molecular → interface | O12: Seconds–days | P12: Multi-cycle | Q12: Mechanical / electrical / adhesion depending network | R12: Build reversible bonds into the material so the same chemistry can repeatedly disconnect and reconnect. | S12: Small gaps; repeat damage; soft/semirigid polymers; hydrogels | T12: Strength–mobility trade-off | U12: Surfaces too far apart; low chain mobility; wrong activation conditions | V12: NR09, NR10, NR14, NR15 | W12: 2026 polymer/hydrogel reviews; enamel paper | X12: High
A13: NR09 | B13: Sacrificial dissipation + recovery | C13: 2 Stabilize + 4 Reconstruct | D13: Extended: sacrificial bond network | E13: Mussel byssus; bone; nacre; tough biological tissues | F13: Prevent catastrophic fracture by consuming energy in reversible secondary interactions. | G13: Load rises → weaker bonds/domain interfaces fail first → energy dissipates → primary backbone survives → weak interactions reform. | H13: Mechanical load/unload | I13: Crack driving force is reduced | J13: Weak reversible interactions | K13: Distributed hierarchy | L13: No long-range transport | M13: Reassociation of sacrificial network | N13: Molecular → mesoscale | O13: Immediate dissipation; recovery minutes–hours | P13: Multi-cycle if bonds recover | Q13: Toughness / fatigue resistance / mechanics | R13: Give the structure reversible 'fuses' that fail before the main load path and can reset afterward. | S13: Impact, fatigue, stretchable structures | T13: Hysteresis / residual strain / slower recovery | U13: Sacrificial network fails irreversibly or does not reform | V13: NR08, NR10, NR14 | W13: Mussel/byssus and tough hydrogel literature | X13: High
A14: NR10 | B14: Hierarchical crack control | C14: 0 Prevent + 2 Stabilize | D14: Extended: hierarchy / crack deflection | E14: Tooth enamel; nacre; bone; fibrous biological composites | F14: Combine stiffness/strength with crack resistance and local repairability. | G14: Aligned or layered hard phase carries load → interfaces redistribute stress/deflect crack → soft/dynamic phase dissipates and heals. | H14: Mechanical stress / crack initiation | I14: Propagation is slowed or redirected | J14: Hard reinforcement + compliant/dynamic interphase | K14: Distributed multiscale architecture | L14: Stress redistribution, not material transport | M14: Crack deflection + local repair | N14: Nano → component | O14: Immediate crack control + later healing | P14: Structural architecture persists | Q14: Strength, toughness, damage tolerance | R14: Separate load bearing and healing across scales so strong domains do not eliminate the mobility needed for repair. | S14: Load-bearing composites where conventional self-healing is too soft | T14: More reinforcement can suppress healing mobility | U14: Interface delamination or fiber failure cannot be restored by matrix healing alone | V14: NR08, NR09, NR16 | W14: 2026 enamel paper; 2026 composites review | X14: High
A15: NR11 | B15: Biomineralize / regrow missing material | C15: 4 Reconstruct | D15: Extended: biomineralization / deposition | E15: Bone/shell formation; bacteria, fungi, algae | F15: Replace lost volume with new solid material under ambient conditions. | G15: Damage exposes pathway + water/nutrients/ions → organism/metabolism or chemistry creates carbonate/mineral → nucleation → growth fills crack. | H15: Moisture; nutrients; ions; pH; metabolism | I15: New material nucleates in defect | J15: Mineral ions + metabolic products | K15: Ambient + embedded/external biological agent | L15: Diffusion / capillarity / growth | M15: Mineral precipitation / growth | N15: Surface → crack volume | O15: Days–weeks | P15: Multi-cycle while viable/resources accessible | Q15: Barrier; durability; sometimes mechanical recovery | R15: Use the damaged void as a reactor: bring precursors to it and grow a compatible solid phase in situ. | S15: Porous mineral materials; wet environments; inaccessible microcracks if agents are embedded | T15: Strong dependence on environmental window and access | U15: Only crack mouth heals; cells die; nutrients depleted; by-products undesirable | V15: NR03, NR05, NR06, NR16 | W15: van der Bergh thesis; B. pseudomycoides study; concrete reviews | X15: High for bacteria; Emerging for fungi/algae
... A20: NR16 | B20: Staged / temporal repair | C20: 2→5 sequence | D20: Extended: sequential response / homeostasis | E20: Hemostasis → inflammation/proliferation → remodeling; plant multistage defense | F20: Optimize for both survival-speed and restoration-quality without forcing one mechanism to do both. | G20: Phase 1 contain/seal → Phase 2 mobilize/reconstruct → Phase 3 remodel/verify → terminate response. | H20: Damage plus changing time/local chemistry | I20: Fast stabilization first | J20: Multiple resources separated by time or layer | K20: Local + networked | L20: Sequential release / recruitment | M20: Hybrid multi-mechanism | N20: Interface → component | O20: Seconds to long remodeling | P20: Repeatability depends on resources | Q20: Multiple functions in sequence | R20: Allocate different repair jobs to different timescales and coordinate handoff between them. | S20: Complex damage; corrosion protection; structural repair where speed and completeness conflict | T20: Coordination complexity | U20: Early seal prevents deeper agent penetration; late phase never activates | V20: NR02, NR03, NR06, NR08, NR11, NR15 | W20: Cremaldi & Bhushan 2018 homeostasis; 2026 time-gradient coating | X20: High

Sheet Biological Primitives
A1: Biological Repair Primitives — the smallest reusable mechanisms beneath the strategies
